Workbook

Sheet Balance Controls
A1: FIRST-RUN BALANCING CONTROLS
A3: Generator | B3: Selected Level | C3: Base Cost | D3: Cost Scaling | E3: Base Heat/s | F3: Base Ash/s | G3: Base Matter/s | H3: Effective Heat Production | I3: Effective Ash Production | J3: Effective Matter Production | K3: Effective Heat Input | L3: Effective Ash Input | M3: Effective Cost | N3: Effective Cost Scaling
A4: Atomic Friction | B4: 35 | C4: 15 | D4: 1.22 | E4: 3 | H4: =F13*F14*F15*F17*F18*F19*F20*F21 -> 1.6928 | I4: =G13*G14*G15*G17*G18*G19*G20*G21 -> 1 | J4: =H13*H14*H15*H17*H18*H19*H20*H21 -> 1 | K4: =I13*I14*I15*I17*I18*I19*I20*I21 -> 1 | L4: =J13*J14*J15*J17*J18*J19*J20*J21 -> 1 | M4: =K13*K14*K15*K17*K18*K19*K20*K21 -> 1 | N4: =L13*L14*L15*L17*L18*L19*L20*L21 -> 1
A5: Molecular Agitation | B5: 20 | C5: 250 | D5: 1.22 | E5: 45 | F5: 0.1 | H5: =F16*F22*F23*F24*F26 -> 1 | I5: =G16*G22*G23*G24*G26 -> 1 | J5: =H16*H22*H23*H24*H26 -> 1 | K5: =I16*I22*I23*I24*I26 -> 1 | L5: =J16*J22*J23*J24*J26 -> 1 | M5: =K16*K22*K23*K24*K26 -> 1 | N5: =L16*L22*L23*L24*L26 -> 1
A6: Lava Mite Colony | B6: 10 | C6: 1000 | D6: 1.22 | E6: -100 | F6: -0.5 | G6: 0.0005 | H6: =F39*F40*F41*F42*F43*F44*F45*F46*F47*F48*F49*F50*F51*F52 -> 1 | I6: =G39*G40*G41*G42*G43*G44*G45*G46*G47*G48*G49*G50*G51*G52 -> 1 | J6: =H39*H40*H41*H42*H43*H44*H45*H46*H47*H48*H49*H50*H51*H52 -> 1 | K6: =I39*I40*I41*I42*I43*I44*I45*I46*I47*I48*I49*I50*I51*I52 -> 1 | L6: =J39*J40*J41*J42*J43*J44*J45*J46*J47*J48*J49*J50*J51*J52 -> 1 | M6: =K39*K40*K41*K42*K43*K44*K45*K46*K47*K48*K49*K50*K51*K52 -> 1 | N6: =L39*L40*L41*L42*L43*L44*L45*L46*L47*L48*L49*L50*L51*L52 -> 1
A7: Infernal Condensation | B7: 5 | C7: 1000 | D7: 1.18 | E7: -1000 | F7: 0.625 | G7: 0.25 | H7: =F25*F31*F32*F33*F34*F35*F36*F37 -> 1 | I7: =G25*G31*G32*G33*G34*G35*G36*G37 -> 1 | J7: =H25*H31*H32*H33*H34*H35*H36*H37 -> 1 | K7: =I25*I31*I32*I33*I34*I35*I36*I37 -> 1 | L7: =J25*J31*J32*J33*J34*J35*J36*J37 -> 1 | M7: =K25*K31*K32*K33*K34*K35*K36*K37 -> 1 | N7: =L25*L31*L32*L33*L34*L35*L36*L37 -> 1
A8: Infernal Forge | B8: 0 | C8: 1000000 | D8: 2 | F8: 5 | G8: 4.5 | H8: =1 -> 1 | I8: =1 -> 1 | J8: =1 -> 1 | K8: =1 -> 1 | L8: =1 -> 1 | M8: =1 -> 1 | N8: =1 -> 1
A11: UPGRADE LEVEL INPUTS
A12: ID | B12: Upgrade | C12: Generator | D12: Level | E12: Max | F12: Heat Prod Factor | G12: Ash Prod Factor | H12: Matter Prod Factor | I12: Heat Input Factor | J12: Ash Input Factor | K12: Cost Factor | L12: Cost Scaling Factor | M12: Notes
A13: atomic_friction_optimization | B13: Atomic Friction Optimization | C13: atomic_friction | D13: 1 | E13: 10 | F13: =1.15^D13 -> 1.15 | G13: 1 | H13: 1 | I13: 1 | J13: 1 | K13: 1 | L13: 1 | M13: 1.15x Heat production per level
A14: atomic_reorganization | B14: Atomic Reorganization | C14: atomic_friction | D14: 1 | E14: 3 | F14: =(1+0.008*B4)^D14 -> 1.28 | G14: 1 | H14: 1 | I14: 1 | J14: 1 | K14: 1 | L14: 1 | M14: 1 + 0.008 × Atomic Friction level, per upgrade level
A15: atomic_friction_refinement | B15: Friction Refinement | C15: atomic_friction | D15: 1 | E15: 5 | F15: =1.15^D15 -> 1.15 | G15: 1 | H15: 1 | I15: 1 | J15: 1 | K15: 1 | L15: 1 | M15: 1.15x Heat production per level
A16: molecular_agitation | B16: Molecular Agitation (unlock) | C16: molecular_agitation | D16: 0 | E16: 1 | F16: 1 | G16: 1 | H16: 1 | I16: 1 | J16: 1 | K16: 1 | L16: 1 | M16: Unlock only
A17: efficient_atomic_processing | B17: Efficient Atomic Processing | C17: atomic_friction | D17: 0 | E17: 1 | F17: 1 | G17: 1 | H17: 1 | I17: 1 | J17: 1 | K17: =0.2^D17 -> 1 | L17: =0.95^D17 -> 1 | M17: 0.95x cost scaling and 0.2x cost per level
A18: atomic_mastery | B18: Atomic Mastery | C18: atomic_friction | D18: 0 | E18: 3 | F18: =1.75^D18 -> 1 | G18: 1 | H18: 1 | I18: 1 | J18: 1 | K18: =0.5^D18 -> 1 | L18: 1 | M18: 1.75x production and 0.5x cost per level
A19: atomic_process_optimization | B19: Atomic Process Optimization | C19: atomic_friction | D19: 0 | E19: 5 | F19: =1.22^D17 -> 1 | G19: 1 | H19: 1 | I19: 1 | J19: 1 | K19: =0.78^D17 -> 1 | L19: 1 | M19: 1.22x production and 0.78x cost per level
A20: crystallization_adaptation | B20: Crystallization Adaptation | C20: atomic_friction | D20: 0 | E20: 1 | F20: 1 | G20: 1 | H20: 1 | I20: 1 | J20: 1 | K20: 1 | L20: 1 | M20: Not represented in this first static sheet
A21: contamination_adaptation | B21: Contamination Adaptation | C21: atomic_friction | D21: 0 | E21: 1 | F21: 1 | G21: 1 | H21: 1 | I21: 1 | J21: 1 | K21: 1 | L21: 1 | M21: Not represented in this first static sheet
A22: molecular_resonance | B22: Molecular Resonance | C22: molecular_agitation | D22: 0 | E22: 10 | F22: =1.15^D22 -> 1 | G22: 1 | H22: 1 | I22: 1 | J22: 1 | K22: 1 | L22: 1 | M22: 1.15x Heat production per level
A23: resonant_containment | B23: Resonant Containment | C23: molecular_agitation | D23: 0 | E23: 3 | F23: =1.55^D23 -> 1 | G23: 1 | H23: 1 | I23: 1 | J23: 1 | K23: 1 | L23: 1 | M23: 1.55x Heat production per level
A24: agitation_optimization | B24: Agitation Optimization | C24: molecular_agitation | D24: 0 | E24: 3 | F24: 1 | G24: =0.9^D24 -> 1 | H24: 1 | I24: 1 | J24: 1 | K24: 1 | L24: =0.97^D24 -> 1 | M24: 0.97x cost scaling and 0.9x Ash production per level
A25: unlock_infernal_condensation | B25: Infernal Condensation (unlock) | C25: thermal_furnace | D25: 0 | E25: 1 | F25: 1 | G25: 1 | H25: 1 | I25: 1 | J25: 1 | K25: 1 | L25: 1 | M25: Unlock only
A26: molecular_agitation_refinement | B26: Agitation Refinement | C26: molecular_agitation | D26: 0 | E26: 10 | F26: =1.18^D26 -> 1 | G26: =1.25^D26 -> 1 | H26: 1 | I26: 1 | J26: 1 | K26: 1 | L26: 1 | M26: 1.18x Heat production and 1.25x Ash production per level
A27: thermal_compressor_optimization | B27: Compression Optimization | C27: thermal_compressor | D27: 0 | E27: 10 | F27: 1 | G27: 1 | H27: 1 | I27: 1 | J27: 1 | K27: 1 | L27: 1 | M27: Generator definition not supplied yet
A28: thermal_compressor_efficiency | B28: Pressure Efficiency | C28: thermal_compressor | D28: 0 | E28: 5 | F28: 1 | G28: 1 | H28: 1 | I28: 1 | J28: 1 | K28: 1 | L28: 1 | M28: Generator definition not supplied yet
A29: high_pressure_compression | B29: High-Pressure Compression | C29: thermal_compressor | D29: 0 | E29: 1 | F29: 1 | G29: 1 | H29: 1 | I29: 1 | J29: 1 | K29: 1 | L29: 1 | M29: Generator definition not supplied yet
A30: thermal_recovery | B30: Thermal Recovery | C30: thermal_compressor | D30: 0 | E30: 1 | F30: 1 | G30: 1 | H30: 1 | I30: 1 | J30: 1 | K30: 1 | L30: 1 | M30: Generator definition not supplied yet
A31: thermal_furnace_optimization | B31: Infernal Condensation Optimization | C31: thermal_furnace | D31: 0 | E31: 10 | F31: 1 | G31: 1 | H31: =1.15^D31 -> 1 | I31: 1 | J31: 1 | K31: 1 | L31: 1 | M31: 1.15x Matter output per level
A32: efficient_thermal_transfer | B32: Efficient Thermal Transfer | C32: thermal_furnace | D32: 0 | E32: 3 | F32: 1 | G32: 1 | H32: 1 | I32: =0.8^D32 -> 1 | J32: 1 | K32: 1 | L32: 1 | M32: 0.8x Heat input per level
A33: thermal_furnace_refinement | B33: Condensation Refinement | C33: thermal_furnace | D33: 0 | E33: 5 | F33: =1.2^D33 -> 1 | G33: =1.2^D33 -> 1 | H33: =1.2^D33 -> 1 | I33: 1 | J33: 1 | K33: 1 | L33: 1 | M33: 1.2x all output per level
A34: thermal_ash_filtration | B34: Ash Filtration | C34: thermal_furnace | D34: 0 | E34: 1 | F34: 1 | G34: =0.7^D34 -> 1 | H34: 1 | I34: 1 | J34: 1 | K34: 1 | L34: 1 | M34: 0.70x Ash output
A35: thermal_furnace_mastery | B35: Infernal Condensation Mastery | C35: thermal_furnace | D35: 0 | E35: 1 | F35: =(1+0.015*B7)^D35 -> 1 | G35: =(1+0.015*B7)^D35 -> 1 | H35: =(1+0.015*B7)^D35 -> 1 | I35: 1 | J35: 1 | K35: 1 | L35: 1 | M35: 1 + 0.015 × generator level, per upgrade level
A36: thermal_furnace_efficiency | B36: Condensation Efficiency | C36: thermal_furnace | D36: 0 | E36: 1 | F36: 1 | G36: 1 | H36: 1 | I36: 1 | J36: 1 | K36: =1 -> 1 | L36: =1 -> 1 | M36: 0.98x cost scaling
A37: thermal_purity | B37: Condensation Purity | C37: thermal_furnace | D37: 0 | E37: 1 | F37: 1 | G37: 1 | H37: =1.6^D37 -> 1 | I37: 1 | J37: 1 | K37: 1 | L37: 1 | M37: 1.6x Matter output
A38: ashen_contamination | B38: Ashen Contamination | C38: GLOBAL | D38: 0 | E38: 1 | F38: 1 | G38: 1 | H38: 1 | I38: 1 | J38: 1 | K38: 1 | L38: 1 | M38: Dynamic realm effect; not represented in this static generator sheet
A39: lava_mite_colony_unlock | B39: Lava Mite Colony | C39: lava_mite_colony | D39: 0 | E39: 1 | F39: 1 | G39: 1 | H39: 1 | I39: 1 | J39: 1 | K39: 1 | L39: 1 | M39: Unlock only
A40: lava_mite_dormancy | B40: Natural Dormancy | C40: lava_mite_colony | D40: 0 | E40: 1 | F40: 1 | G40: 1 | H40: 1 | I40: 1 | J40: 1 | K40: 1 | L40: 1 | M40: Time-dependent; not represented in static production
A41: essence_influence | B41: Essence Influence | C41: lava_mite_colony | D41: 0 | E41: 1 | F41: 1 | G41: 1 | H41: 1 | I41: 1 | J41: 1 | K41: 1 | L41: 1 | M41: Requires Essence/resource simulation
A42: lava_mite_husbandry | B42: Lava Mite Husbandry | C42: lava_mite_colony | D42: 0 | E42: 5 | F42: 1 | G42: 1 | H42: 1 | I42: 1 | J42: 1 | K42: =0.9^D42 -> 1 | L42: 1 | M42: 0.9x generator level cost per level
A43: lava_mite_refinement | B43: Lava Mite Breeding | C43: lava_mite_colony | D43: 0 | E43: 5 | F43: 1 | G43: 1 | H43: 1 | I43: 1 | J43: =1.15^D43 -> 1 | K43: 1 | L43: 1 | M43: 1.15x Ash consumption per level
...

Sheet Base rates
C2: Base ratio | D2: 1 ash costs 200 heat to remove
D3: 1 matter costs 4500 heat
E6: AF | F6: MA | G6: MITES | H6: COND | I6: FURN | K6: Forge
C8: PRODUCTION | D8: Heat | E8: 3 | F8: 45 | G8: -100 | H8: -1000 | I8: 7500
C9: RATES PER SEC | D9: Ash | F9: 0.1 | G9: -0.5 | H9: 0.625 | I9: 2.5
D10: Matter | H10: 0.25 | I10: -1
D11: Essence
C24: COSTS
C26: res type | E26: Heat | F26: Heat | G26: Heat | H26: Heat | I26: Matter
C28: base | E28: 15 | F28: 250 | G28: 1000 | H28: 5000 | I28: 6
C29: Heatnormalized | E29: 15 | F29: 250 | G29: 1000 | H29: 5000 | I29: 21000
C30: scaling | E30: 1.22 | F30: 1.22 | G30: 1.22 | H30: 1.22 | I30: 1.22
F33: 1 ash per 450 heat | G33: 200 heat to remove 1 ash | H33: 4000 heat makes 1 matter and 2,5 ash | I33: 4500 H in M into 7500 H
F34: -200 in ash | H34: 500 in ash | I34: 500 in ash
C35: FINAL | E35: 3hps | F35: 25hps | H35: 1M = 4000+500 = 4500M | I35: 4500 to 7000

Sheet Atomic friction
A2: BALANCING LINK
A3: Selected generator level | B3: ='Balance Controls'!B4 -> 35
A4: Effective Heat production factor | B4: ='Balance Controls'!H4 -> 1.6928
A5: Effective Ash production factor | B5: ='Balance Controls'!I4 -> 1 | H5: Name
A6: Effective Matter production factor | B6: ='Balance Controls'!J4 -> 1 | H6: Base Cost | I6: 15
A7: Effective Heat input factor | B7: ='Balance Controls'!K4 -> 1 | H7: Scaling | I7: 1.22
A8: Effective Ash input factor | B8: ='Balance Controls'!L4 -> 1 | H8: Production rate normalized | I8: 3
A9: Effective level cost factor | B9: ='Balance Controls'!M4 -> 1
A10: Effective cost scaling | B10: ='Balance Controls'!N4 -> 1 | K10: Level | L10: Next cost | M10: Total cost | N10: Production/s | O10: Time to buy next
K11: 0 | L11: =$I$6*($I$7^K11) -> 15 | N11: =K11*$I$8*$B$4*(1+0.008*K11)^'Balance Controls'!$D$14 -> 0 | O11: =L11/N11 -> #DIV/0!
K12: 1 | L12: =$I$6*($I$7^K12) -> 18.3 | N12: =K12*$I$8*$B$4*(1+0.008*K12)^'Balance Controls'!$D$14 -> 5.1190272 | O12: =L12/N12 -> 3.574898
K13: 2 | L13: =$I$6*($I$7^K13) -> 22.326 | N13: =K13*$I$8*$B$4*(1+0.008*K13)^'Balance Controls'!$D$14 -> 10.319309 | O13: =L13/N13 -> 2.163517
K14: 3 | L14: =$I$6*($I$7^K14) -> 27.23772 | N14: =K14*$I$8*$B$4*(1+0.008*K14)^'Balance Controls'!$D$14 -> 15.600845 | O14: =L14/N14 -> 1.7459131
K15: 4 | L15: =$I$6*($I$7^K15) -> 33.230018 | N15: =K15*$I$8*$B$4*(1+0.008*K15)^'Balance Controls'!$D$14 -> 20.963635 | O15: =L15/N15 -> 1.5851267
K16: 5 | L16: =$I$6*($I$7^K16) -> 40.540622 | N16: =K16*$I$8*$B$4*(1+0.008*K16)^'Balance Controls'!$D$14 -> 26.40768 | O16: =L16/N16 -> 1.535183
K17: 6 | L17: =$I$6*($I$7^K17) -> 49.459559 | N17: =K17*$I$8*$B$4*(1+0.008*K17)^'Balance Controls'!$D$14 -> 31.932979 | O17: =L17/N17 -> 1.5488552
K18: 7 | L18: =$I$6*($I$7^K18) -> 60.340662 | N18: =K18*$I$8*$B$4*(1+0.008*K18)^'Balance Controls'!$D$14 -> 37.539533 | O18: =L18/N18 -> 1.6073898
K19: 8 | L19: =$I$6*($I$7^K19) -> 73.615608 | N19: =K19*$I$8*$B$4*(1+0.008*K19)^'Balance Controls'!$D$14 -> 43.227341 | O19: =L19/N19 -> 1.7029872
K20: 9 | L20: =$I$6*($I$7^K20) -> 89.811042 | N20: =K20*$I$8*$B$4*(1+0.008*K20)^'Balance Controls'!$D$14 -> 48.996403 | O20: =L20/N20 -> 1.833013
K21: 10 | L21: =$I$6*($I$7^K21) -> 109.56947 | N21: =K21*$I$8*$B$4*(1+0.008*K21)^'Balance Controls'!$D$14 -> 54.84672 | O21: =L21/N21 -> 1.9977397
K22: 11 | L22: =$I$6*($I$7^K22) -> 133.67475 | N22: =K22*$I$8*$B$4*(1+0.008*K22)^'Balance Controls'!$D$14 -> 60.778291 | O22: =L22/N22 -> 2.1993832
... K331: 320 | L331: =$I$6*($I$7^K331) -> 6.4749598e+28 | N331: =K331*$I$8*$B$4*(1+0.008*K331)^'Balance Controls'!$D$14 -> 5785.3133 | O331: =L331/N331 -> 1.1192064e+25

Sheet Molecular Agitation
A2: BALANCING LINK
A3: Selected generator level | B3: ='Balance Controls'!B5 -> 20 | I3: 1 ash = -200heat
A4: Effective Heat production factor | B4: ='Balance Controls'!H5 -> 1
A5: Effective Ash production factor | B5: ='Balance Controls'!I5 -> 1 | H5: Name
A6: Effective Matter production factor | B6: ='Balance Controls'!J5 -> 1 | H6: Base Cost | I6: 250
A7: Effective Heat input factor | B7: ='Balance Controls'!K5 -> 1 | H7: Scaling | I7: 1.22
A8: Effective Ash input factor | B8: ='Balance Controls'!L5 -> 1 | H8: Production rate normalized | I8: 45
A9: Effective level cost factor | B9: ='Balance Controls'!M5 -> 1
A10: Effective cost scaling | B10: ='Balance Controls'!N5 -> 1 | H10: HEAT | I10: 45 | K10: Level | L10: Next cost | M10: Total cost | N10: Production/s | O10: Time to buy next | Q10: Ash/s
H11: ASH | I11: 0.1 | K11: 0 | L11: =$I$6*($I$7^K11) -> 250 | N11: =K11*$I$8*$B$4 -> 0 | O11: =L11/N11 -> #DIV/0! | Q11: =K11*$I$11*$B$5 -> 0
K12: 1 | L12: =$I$6*($I$7^K12) -> 305 | N12: =K12*$I$8*$B$4 -> 45 | O12: =L12/N12 -> 6.7777778 | Q12: =K12*$I$11*$B$5 -> 0.1
K13: 2 | L13: =$I$6*($I$7^K13) -> 372.1 | N13: =K13*$I$8*$B$4 -> 90 | O13: =L13/N13 -> 4.1344444 | Q13: =K13*$I$11*$B$5 -> 0.2
K14: 3 | L14: =$I$6*($I$7^K14) -> 453.962 | N14: =K14*$I$8*$B$4 -> 135 | O14: =L14/N14 -> 3.3626815 | Q14: =K14*$I$11*$B$5 -> 0.3
K15: 4 | L15: =$I$6*($I$7^K15) -> 553.83364 | N15: =K15*$I$8*$B$4 -> 180 | O15: =L15/N15 -> 3.0768536 | Q15: =K15*$I$11*$B$5 -> 0.4
K16: 5 | L16: =$I$6*($I$7^K16) -> 675.67704 | N16: =K16*$I$8*$B$4 -> 225 | O16: =L16/N16 -> 3.0030091 | Q16: =K16*$I$11*$B$5 -> 0.5
K17: 6 | L17: =$I$6*($I$7^K17) -> 824.32599 | N17: =K17*$I$8*$B$4 -> 270 | O17: =L17/N17 -> 3.0530592 | Q17: =K17*$I$11*$B$5 -> 0.6
K18: 7 | L18: =$I$6*($I$7^K18) -> 1005.6777 | N18: =K18*$I$8*$B$4 -> 315 | O18: =L18/N18 -> 3.1926276 | Q18: =K18*$I$11*$B$5 -> 0.7
K19: 8 | L19: =$I$6*($I$7^K19) -> 1226.9268 | N19: =K19*$I$8*$B$4 -> 360 | O19: =L19/N19 -> 3.40813 | Q19: =K19*$I$11*$B$5 -> 0.8
K20: 9 | L20: =$I$6*($I$7^K20) -> 1496.8507 | N20: =K20*$I$8*$B$4 -> 405 | O20: =L20/N20 -> 3.6959277 | Q20: =K20*$I$11*$B$5 -> 0.9
K21: 10 | L21: =$I$6*($I$7^K21) -> 1826.1579 | N21: =K21*$I$8*$B$4 -> 450 | O21: =L21/N21 -> 4.0581286 | Q21: =K21*$I$11*$B$5 -> 1
K22: 11 | L22: =$I$6*($I$7^K22) -> 2227.9126 | N22: =K22*$I$8*$B$4 -> 495 | O22: =L22/N22 -> 4.5008335 | Q22: =K22*$I$11*$B$5 -> 1.1
K23: 12 | L23: =$I$6*($I$7^K23) -> 2718.0533 | N23: =K23*$I$8*$B$4 -> 540 | O23: =L23/N23 -> 5.0334321 | Q23: =K23*$I$11*$B$5 -> 1.2
... K331: 320 | L331: =$I$6*($I$7^K331) -> 1.07916e+30 | N331: =K331*$I$8*$B$4 -> 14400 | O331: =L331/N331 -> 7.4941664e+25 | Q331: =K331*$I$11*$B$5 -> 32

Sheet Lava Mites
A2: BALANCING LINK
A3: Selected generator level | B3: ='Balance Controls'!B6 -> 10 | I3: 1 ash = -200heat
A4: Effective Heat production factor | B4: ='Balance Controls'!H6 -> 1
A5: Effective Ash production factor | B5: ='Balance Controls'!I6 -> 1 | H5: Name
A6: Effective Matter production factor | B6: ='Balance Controls'!J6 -> 1 | H6: Base Cost | I6: 1000
A7: Effective Heat input factor | B7: ='Balance Controls'!K6 -> 1 | H7: Scaling | I7: 1.22
A8: Effective Ash input factor | B8: ='Balance Controls'!L6 -> 1 | H8: Production rate normalized | I8: 25 | N8: Uses mol agi prod rates
A9: Effective level cost factor | B9: ='Balance Controls'!M6 -> 1
A10: Effective cost scaling | B10: ='Balance Controls'!N6 -> 1 | H10: HEAT | I10: -100 | K10: Level | L10: Next cost | M10: Total cost | N10: Production/s | O10: Time to buy next | Q10: Ash/s | R10: Ash/s
H11: ASH | I11: -0.5 | K11: 0 | L11: =$I$6*($I$7^K11) -> 1000 | M11: 0 | N11: =K11*$I$8 -> 0 | O11: =L11/N11 -> #DIV/0! | Q11: =K11*$I$11*$B$8 -> 0 | R11: =K11*$I$12 -> 0
H12: ESSENCE | I12: 0.0005 | K12: 1 | L12: =$I$6*($I$7^K12) -> 1220 | M12: =M11+L11 -> 1000 | N12: =K12*$I$8 -> 25 | O12: =L12/N12 -> 48.8 | Q12: =K12*$I$11*$B$8 -> -0.5 | R12: =K12*$I$12 -> 0.0005
K13: 2 | L13: =$I$6*($I$7^K13) -> 1488.4 | M13: =M12+L12 -> 2220 | N13: =K13*$I$8 -> 50 | O13: =L13/N13 -> 29.768 | Q13: =K13*$I$11*$B$8 -> -1 | R13: =K13*$I$12 -> 0.001
K14: 3 | L14: =$I$6*($I$7^K14) -> 1815.848 | M14: =M13+L13 -> 3708.4 | N14: =K14*$I$8 -> 75 | O14: =L14/N14 -> 24.211307 | Q14: =K14*$I$11*$B$8 -> -1.5 | R14: =K14*$I$12 -> 0.0015
K15: 4 | L15: =$I$6*($I$7^K15) -> 2215.3346 | M15: =M14+L14 -> 5524.248 | N15: =K15*$I$8 -> 100 | O15: =L15/N15 -> 22.153346 | Q15: =K15*$I$11*$B$8 -> -2 | R15: =K15*$I$12 -> 0.002
K16: 5 | L16: =$I$6*($I$7^K16) -> 2702.7082 | M16: =M15+L15 -> 7739.5826 | N16: =K16*$I$8 -> 125 | O16: =L16/N16 -> 21.621665 | Q16: =K16*$I$11*$B$8 -> -2.5 | R16: =K16*$I$12 -> 0.0025
K17: 6 | L17: =$I$6*($I$7^K17) -> 3297.304 | M17: =M16+L16 -> 10442.291 | N17: =K17*$I$8 -> 150 | O17: =L17/N17 -> 21.982026 | Q17: =K17*$I$11*$B$8 -> -3 | R17: =K17*$I$12 -> 0.003
K18: 7 | L18: =$I$6*($I$7^K18) -> 4022.7108 | M18: =M17+L17 -> 13739.595 | N18: =K18*$I$8 -> 175 | O18: =L18/N18 -> 22.986919 | Q18: =K18*$I$11*$B$8 -> -3.5 | R18: =K18*$I$12 -> 0.0035
K19: 8 | L19: =$I$6*($I$7^K19) -> 4907.7072 | M19: =M18+L18 -> 17762.306 | N19: =K19*$I$8 -> 200 | O19: =L19/N19 -> 24.538536 | Q19: =K19*$I$11*$B$8 -> -4 | R19: =K19*$I$12 -> 0.004
K20: 9 | L20: =$I$6*($I$7^K20) -> 5987.4028 | M20: =M19+L19 -> 22670.013 | N20: =K20*$I$8 -> 225 | O20: =L20/N20 -> 26.610679 | Q20: =K20*$I$11*$B$8 -> -4.5 | R20: =K20*$I$12 -> 0.0045
K21: 10 | L21: =$I$6*($I$7^K21) -> 7304.6314 | M21: =M20+L20 -> 28657.416 | N21: =K21*$I$8 -> 250 | O21: =L21/N21 -> 29.218526 | Q21: =K21*$I$11*$B$8 -> -5 | R21: =K21*$I$12 -> 0.005
K22: 11 | L22: =$I$6*($I$7^K22) -> 8911.6503 | M22: =M21+L21 -> 35962.047 | N22: =K22*$I$8 -> 275 | O22: =L22/N22 -> 32.406001 | Q22: =K22*$I$11*$B$8 -> -5.5 | R22: =K22*$I$12 -> 0.0055
K23: 12 | L23: =$I$6*($I$7^K23) -> 10872.213 | M23: =M22+L22 -> 44873.697 | N23: =K23*$I$8 -> 300 | O23: =L23/N23 -> 36.240711 | Q23: =K23*$I$11*$B$8 -> -6 | R23: =K23*$I$12 -> 0.006
K24: 13 | L24: =$I$6*($I$7^K24) -> 13264.1 | M24: =M23+L23 -> 55745.911 | N24: =K24*$I$8 -> 325 | O24: =L24/N24 -> 40.812616 | Q24: =K24*$I$11*$B$8 -> -6.5 | R24: =K24*$I$12 -> 0.0065
... K331: 320 | L331: =$I$6*($I$7^K331) -> 4.3166399e+30 | M331: =M330+L330 -> 1.962109e+31 | N331: =K331*$I$8 -> 8000 | O331: =L331/N331 -> 5.3957998e+26 | Q331: =K331*$I$11*$B$8 -> -160 | R331: =K331*$I$12 -> 0.16

Sheet Infernal Condensation
A2: BALANCING LINK
A3: Selected generator level | B3: ='Balance Controls'!B7 -> 5 | I3: 1 ash = -200heat
A4: Effective Heat production factor | B4: ='Balance Controls'!H7 -> 1
A5: Effective Ash production factor | B5: ='Balance Controls'!I7 -> 1 | H5: Name
A6: Effective Matter production factor | B6: ='Balance Controls'!J7 -> 1 | H6: Base Cost | I6: 1000
A7: Effective Heat input factor | B7: ='Balance Controls'!K7 -> 1 | H7: Scaling | I7: 1.18
A8: Effective Ash input factor | B8: ='Balance Controls'!L7 -> 1 | H8: Production rate normalized | I8: 25 | N8: Uses mol agi prod rates
A9: Effective level cost factor | B9: ='Balance Controls'!M7 -> 1
A10: Effective cost scaling | B10: ='Balance Controls'!N7 -> 1 | H10: HEAT | I10: -1000 | K10: Level | L10: Next cost | M10: Total cost | N10: Production/s | O10: Time to buy next | Q10: Ash/s | R10: Matter/s
H11: ASH | I11: 0.625 | K11: 0 | L11: =$I$6*($I$7^K11) -> 1000 | N11: =K11*$I$8*$B$10 -> 0 | O11: =L11/N11 -> #DIV/0! | Q11: =K11*$I$11*$B$5 -> 0 | R11: =K11*$I$12*$B$6*(1+0.015*K11)^'Balance Controls'!$D$35 -> 0
H12: Matter | I12: 0.25 | K12: 1 | L12: =$I$6*($I$7^K12) -> 1180 | N12: =K12*$I$8*$B$10 -> 25 | O12: =L12/N12 -> 47.2 | Q12: =K12*$I$11*$B$5 -> 0.625 | R12: =K12*$I$12*$B$6*(1+0.015*K12)^'Balance Controls'!$D$35 -> 0.25
D13: COND | K13: 2 | L13: =$I$6*($I$7^K13) -> 1392.4 | N13: =K13*$I$8*$B$10 -> 50 | O13: =L13/N13 -> 27.848 | Q13: =K13*$I$11*$B$5 -> 1.25 | R13: =K13*$I$12*$B$6*(1+0.015*K13)^'Balance Controls'!$D$35 -> 0.5
K14: 3 | L14: =$I$6*($I$7^K14) -> 1643.032 | N14: =K14*$I$8*$B$10 -> 75 | O14: =L14/N14 -> 21.907093 | Q14: =K14*$I$11*$B$5 -> 1.875 | R14: =K14*$I$12*$B$6*(1+0.015*K14)^'Balance Controls'!$D$35 -> 0.75
D15: -1000 | K15: 4 | L15: =$I$6*($I$7^K15) -> 1938.7778 | N15: =K15*$I$8*$B$10 -> 100 | O15: =L15/N15 -> 19.387778 | Q15: =K15*$I$11*$B$5 -> 2.5 | R15: =K15*$I$12*$B$6*(1+0.015*K15)^'Balance Controls'!$D$35 -> 1
D16: 0.625 | K16: 5 | L16: =$I$6*($I$7^K16) -> 2287.7578 | N16: =K16*$I$8*$B$10 -> 125 | O16: =L16/N16 -> 18.302062 | Q16: =K16*$I$11*$B$5 -> 3.125 | R16: =K16*$I$12*$B$6*(1+0.015*K16)^'Balance Controls'!$D$35 -> 1.25
D17: 0.25 | K17: 6 | L17: =$I$6*($I$7^K17) -> 2699.5542 | N17: =K17*$I$8*$B$10 -> 150 | O17: =L17/N17 -> 17.997028 | Q17: =K17*$I$11*$B$5 -> 3.75 | R17: =K17*$I$12*$B$6*(1+0.015*K17)^'Balance Controls'!$D$35 -> 1.5
K18: 7 | L18: =$I$6*($I$7^K18) -> 3185.4739 | N18: =K18*$I$8*$B$10 -> 175 | O18: =L18/N18 -> 18.202708 | Q18: =K18*$I$11*$B$5 -> 4.375 | R18: =K18*$I$12*$B$6*(1+0.015*K18)^'Balance Controls'!$D$35 -> 1.75
K19: 8 | L19: =$I$6*($I$7^K19) -> 3758.8592 | N19: =K19*$I$8*$B$10 -> 200 | O19: =L19/N19 -> 18.794296 | Q19: =K19*$I$11*$B$5 -> 5 | R19: =K19*$I$12*$B$6*(1+0.015*K19)^'Balance Controls'!$D$35 -> 2
K20: 9 | L20: =$I$6*($I$7^K20) -> 4435.4539 | N20: =K20*$I$8*$B$10 -> 225 | O20: =L20/N20 -> 19.713128 | Q20: =K20*$I$11*$B$5 -> 5.625 | R20: =K20*$I$12*$B$6*(1+0.015*K20)^'Balance Controls'!$D$35 -> 2.25
K21: 10 | L21: =$I$6*($I$7^K21) -> 5233.8356 | N21: =K21*$I$8*$B$10 -> 250 | O21: =L21/N21 -> 20.935342 | Q21: =K21*$I$11*$B$5 -> 6.25 | R21: =K21*$I$12*$B$6*(1+0.015*K21)^'Balance Controls'!$D$35 -> 2.5
K22: 11 | L22: =$I$6*($I$7^K22) -> 6175.926 | N22: =K22*$I$8*$B$10 -> 275 | O22: =L22/N22 -> 22.457913 | Q22: =K22*$I$11*$B$5 -> 6.875 | R22: =K22*$I$12*$B$6*(1+0.015*K22)^'Balance Controls'!$D$35 -> 2.75
K23: 12 | L23: =$I$6*($I$7^K23) -> 7287.5926 | N23: =K23*$I$8*$B$10 -> 300 | O23: =L23/N23 -> 24.291975 | Q23: =K23*$I$11*$B$5 -> 7.5 | R23: =K23*$I$12*$B$6*(1+0.015*K23)^'Balance Controls'!$D$35 -> 3
K24: 13 | L24: =$I$6*($I$7^K24) -> 8599.3593 | N24: =K24*$I$8*$B$10 -> 325 | O24: =L24/N24 -> 26.459567 | Q24: =K24*$I$11*$B$5 -> 8.125 | R24: =K24*$I$12*$B$6*(1+0.015*K24)^'Balance Controls'!$D$35 -> 3.25
K25: 14 | L25: =$I$6*($I$7^K25) -> 10147.244 | N25: =K25*$I$8*$B$10 -> 350 | O25: =L25/N25 -> 28.992126 | Q25: =K25*$I$11*$B$5 -> 8.75 | R25: =K25*$I$12*$B$6*(1+0.015*K25)^'Balance Controls'!$D$35 -> 3.5
K26: 15 | L26: =$I$6*($I$7^K26) -> 11973.748 | N26: =K26*$I$8*$B$10 -> 375 | O26: =L26/N26 -> 31.929994 | Q26: =K26*$I$11*$B$5 -> 9.375 | R26: =K26*$I$12*$B$6*(1+0.015*K26)^'Balance Controls'!$D$35 -> 3.75
K27: 16 | L27: =$I$6*($I$7^K27) -> 14129.023 | N27: =K27*$I$8*$B$10 -> 400 | O27: =L27/N27 -> 35.322556 | Q27: =K27*$I$11*$B$5 -> 10 | R27: =K27*$I$12*$B$6*(1+0.015*K27)^'Balance Controls'!$D$35 -> 4
K28: 17 | L28: =$I$6*($I$7^K28) -> 16672.247 | N28: =K28*$I$8*$B$10 -> 425 | O28: =L28/N28 -> 39.228815 | Q28: =K28*$I$11*$B$5 -> 10.625 | R28: =K28*$I$12*$B$6*(1+0.015*K28)^'Balance Controls'!$D$35 -> 4.25
K29: 18 | L29: =$I$6*($I$7^K29) -> 19673.251 | N29: =K29*$I$8*$B$10 -> 450 | O29: =L29/N29 -> 43.718335 | Q29: =K29*$I$11*$B$5 -> 11.25 | R29: =K29*$I$12*$B$6*(1+0.015*K29)^'Balance Controls'!$D$35 -> 4.5
... K32: 21 | L32: =$I$6*($I$7^K32) -> 32323.781 | N32: =K32*$I$8*$B$10 -> 525 | O32: =L32/N32 -> 61.569106 | Q32: =K32*$I$11*$B$5 -> 13.125 | R32: =K32*$I$12*$B$6*(1+0.015*K32)^'Balance Controls'!$D$35 -> 5.25
D33: Heat | K33: 22 | L33: =$I$6*($I$7^K33) -> 38142.061 | N33: =K33*$I$8*$B$10 -> 550 | O33: =L33/N33 -> 69.349203 | Q33: =K33*$I$11*$B$5 -> 13.75 | R33: =K33*$I$12*$B$6*(1+0.015*K33)^'Balance Controls'!$D$35 -> 5.5
K34: 23 | L34: =$I$6*($I$7^K34) -> 45007.632 | N34: =K34*$I$8*$B$10 -> 575 | O34: =L34/N34 -> 78.274143 | Q34: =K34*$I$11*$B$5 -> 14.375 | R34: =K34*$I$12*$B$6*(1+0.015*K34)^'Balance Controls'!$D$35 -> 5.75
D35: 5000 | K35: 24 | L35: =$I$6*($I$7^K35) -> 53109.006 | N35: =K35*$I$8*$B$10 -> 600 | O35: =L35/N35 -> 88.51501 | Q35: =K35*$I$11*$B$5 -> 15 | R35: =K35*$I$12*$B$6*(1+0.015*K35)^'Balance Controls'!$D$35 -> 6
D36: 5000 | K36: 25 | L36: =$I$6*($I$7^K36) -> 62668.627 | N36: =K36*$I$8*$B$10 -> 625 | O36: =L36/N36 -> 100.2698 | Q36: =K36*$I$11*$B$5 -> 15.625 | R36: =K36*$I$12*$B$6*(1+0.015*K36)^'Balance Controls'!$D$35 -> 6.25
D37: 1.22 | K37: 26 | L37: =$I$6*($I$7^K37) -> 73948.98 | N37: =K37*$I$8*$B$10 -> 650 | O37: =L37/N37 -> 113.76766 | Q37: =K37*$I$11*$B$5 -> 16.25 | R37: =K37*$I$12*$B$6*(1+0.015*K37)^'Balance Controls'!$D$35 -> 6.5
K38: 27 | L38: =$I$6*($I$7^K38) -> 87259.797 | N38: =K38*$I$8*$B$10 -> 675 | O38: =L38/N38 -> 129.27377 | Q38: =K38*$I$11*$B$5 -> 16.875 | R38: =K38*$I$12*$B$6*(1+0.015*K38)^'Balance Controls'!$D$35 -> 6.75
K39: 28 | L39: =$I$6*($I$7^K39) -> 102966.56 | N39: =K39*$I$8*$B$10 -> 700 | O39: =L39/N39 -> 147.09509 | Q39: =K39*$I$11*$B$5 -> 17.5 | R39: =K39*$I$12*$B$6*(1+0.015*K39)^'Balance Controls'!$D$35 -> 7
D40: 4000 heat makes 1 matter and 2,5 ash | K40: 29 | L40: =$I$6*($I$7^K40) -> 121500.54 | N40: =K40*$I$8*$B$10 -> 725 | O40: =L40/N40 -> 167.58695 | Q40: =K40*$I$11*$B$5 -> 18.125 | R40: =K40*$I$12*$B$6*(1+0.015*K40)^'Balance Controls'!$D$35 -> 7.25
D41: 500 in ash | K41: 30 | L41: =$I$6*($I$7^K41) -> 143370.64 | N41: =K41*$I$8*$B$10 -> 750 | O41: =L41/N41 -> 191.16085 | Q41: =K41*$I$11*$B$5 -> 18.75 | R41: =K41*$I$12*$B$6*(1+0.015*K41)^'Balance Controls'!$D$35 -> 7.5
D42: 1M = 4000+500 = 4500M | K42: 31 | L42: =$I$6*($I$7^K42) -> 169177.35 | N42: =K42*$I$8*$B$10 -> 775 | O42: =L42/N42 -> 218.29336 | Q42: =K42*$I$11*$B$5 -> 19.375 | R42: =K42*$I$12*$B$6*(1+0.015*K42)^'Balance Controls'!$D$35 -> 7.75
K43: 32 | L43: =$I$6*($I$7^K43) -> 199629.28 | N43: =K43*$I$8*$B$10 -> 800 | O43: =L43/N43 -> 249.5366 | Q43: =K43*$I$11*$B$5 -> 20 | R43: =K43*$I$12*$B$6*(1+0.015*K43)^'Balance Controls'!$D$35 -> 8
...

Sheet Blad7

Sheet Blad8
